# SOME DESCRIPTIVE TITLE.
# Copyright (C) 2001-2024, Python Software Foundation
# This file is distributed under the same license as the Python package.
# FIRST AUTHOR <EMAIL@ADDRESS>, YEAR.
# 
# Translators:
# Dmytro Kazanzhy, 2022
# Nadiia Gorash <nmaiboroda@gmail.com>, 2022
# 
#, fuzzy
msgid ""
msgstr ""
"Project-Id-Version: Python 3.13\n"
"Report-Msgid-Bugs-To: \n"
"POT-Creation-Date: 2024-11-15 14:18+0000\n"
"PO-Revision-Date: 2021-06-28 01:50+0000\n"
"Last-Translator: Nadiia Gorash <nmaiboroda@gmail.com>, 2022\n"
"Language-Team: Ukrainian (https://app.transifex.com/python-doc/teams/5390/uk/)\n"
"MIME-Version: 1.0\n"
"Content-Type: text/plain; charset=UTF-8\n"
"Content-Transfer-Encoding: 8bit\n"
"Language: uk\n"
"Plural-Forms: nplurals=4; plural=(n % 1 == 0 && n % 10 == 1 && n % 100 != 11 ? 0 : n % 1 == 0 && n % 10 >= 2 && n % 10 <= 4 && (n % 100 < 12 || n % 100 > 14) ? 1 : n % 1 == 0 && (n % 10 ==0 || (n % 10 >=5 && n % 10 <=9) || (n % 100 >=11 && n % 100 <=14 )) ? 2: 3);\n"

#: ../../tutorial/errors.rst:5
msgid "Errors and Exceptions"
msgstr "Помилки та винятки"

#: ../../tutorial/errors.rst:7
msgid ""
"Until now error messages haven't been more than mentioned, but if you have "
"tried out the examples you have probably seen some.  There are (at least) "
"two distinguishable kinds of errors: *syntax errors* and *exceptions*."
msgstr ""
"До цього часу повідомлення про помилки не згадувалися, але якщо ви "
"спробували приклади, ви, ймовірно, бачили деякі. Існує (принаймні) два "
"різновиди помилок: *синтаксичні помилки* та *винятки*."

#: ../../tutorial/errors.rst:15
msgid "Syntax Errors"
msgstr "Синтаксичні помилки"

#: ../../tutorial/errors.rst:17
msgid ""
"Syntax errors, also known as parsing errors, are perhaps the most common "
"kind of complaint you get while you are still learning Python::"
msgstr ""
"Синтаксичні помилки, також відомі як помилки синтаксичного аналізу, є, "
"мабуть, найпоширенішим типом скарг, які ви отримуєте, поки вивчаєте Python::"

#: ../../tutorial/errors.rst:20
msgid ""
">>> while True print('Hello world')\n"
"  File \"<stdin>\", line 1\n"
"    while True print('Hello world')\n"
"               ^^^^^\n"
"SyntaxError: invalid syntax"
msgstr ""

#: ../../tutorial/errors.rst:26
msgid ""
"The parser repeats the offending line and displays little 'arrow's pointing "
"at the token in the line where the error was detected.  The error may be "
"caused by the absence of a token *before* the indicated token.  In the "
"example, the error is detected at the function :func:`print`, since a colon "
"(``':'``) is missing before it.  File name and line number are printed so "
"you know where to look in case the input came from a script."
msgstr ""

#: ../../tutorial/errors.rst:37
msgid "Exceptions"
msgstr "Винятки"

#: ../../tutorial/errors.rst:39
msgid ""
"Even if a statement or expression is syntactically correct, it may cause an "
"error when an attempt is made to execute it. Errors detected during "
"execution are called *exceptions* and are not unconditionally fatal: you "
"will soon learn how to handle them in Python programs.  Most exceptions are "
"not handled by programs, however, and result in error messages as shown "
"here::"
msgstr ""
"Навіть якщо оператор або вираз синтаксично правильний, це може спричинити "
"помилку під час спроби його виконання. Помилки, виявлені під час виконання, "
"називаються *винятками* і не є безумовно фатальними: незабаром ви "
"дізнаєтесь, як їх обробляти в програмах Python. Однак більшість винятків не "
"обробляються програмами, і вони призводять до повідомлень про помилки, як "
"показано тут::"

#: ../../tutorial/errors.rst:45
msgid ""
">>> 10 * (1/0)\n"
"Traceback (most recent call last):\n"
"  File \"<stdin>\", line 1, in <module>\n"
"    10 * (1/0)\n"
"          ~^~\n"
"ZeroDivisionError: division by zero\n"
">>> 4 + spam*3\n"
"Traceback (most recent call last):\n"
"  File \"<stdin>\", line 1, in <module>\n"
"    4 + spam*3\n"
"        ^^^^\n"
"NameError: name 'spam' is not defined\n"
">>> '2' + 2\n"
"Traceback (most recent call last):\n"
"  File \"<stdin>\", line 1, in <module>\n"
"    '2' + 2\n"
"    ~~~~^~~\n"
"TypeError: can only concatenate str (not \"int\") to str"
msgstr ""

#: ../../tutorial/errors.rst:64
msgid ""
"The last line of the error message indicates what happened. Exceptions come "
"in different types, and the type is printed as part of the message: the "
"types in the example are :exc:`ZeroDivisionError`, :exc:`NameError` and "
":exc:`TypeError`. The string printed as the exception type is the name of "
"the built-in exception that occurred.  This is true for all built-in "
"exceptions, but need not be true for user-defined exceptions (although it is"
" a useful convention). Standard exception names are built-in identifiers "
"(not reserved keywords)."
msgstr ""
"Останній рядок повідомлення про помилку вказує на те, що сталося. Винятки "
"бувають різних типів, і тип друкується як частина повідомлення: типи в "
"прикладі: :exc:`ZeroDivisionError`, :exc:`NameError` і :exc:`TypeError`. "
"Рядок, надрукований як тип винятку, є назвою вбудованого винятку, який "
"стався. Це справедливо для всіх вбудованих винятків, але не обов’язково для "
"винятків, визначених користувачем (хоча це корисна угода). Стандартні назви "
"винятків є вбудованими ідентифікаторами (а не зарезервованими ключовими "
"словами)."

#: ../../tutorial/errors.rst:72
msgid ""
"The rest of the line provides detail based on the type of exception and what"
" caused it."
msgstr ""
"Решта рядка надає деталі на основі типу винятку та причини його виникнення."

#: ../../tutorial/errors.rst:75
msgid ""
"The preceding part of the error message shows the context where the "
"exception occurred, in the form of a stack traceback. In general it contains"
" a stack traceback listing source lines; however, it will not display lines "
"read from standard input."
msgstr ""
"Попередня частина повідомлення про помилку показує контекст, у якому сталася"
" виняток, у формі зворотного стека. Загалом, він містить зворотне трасування"
" стека зі списком вихідних рядків; однак він не відображатиме рядки, "
"прочитані зі стандартного введення."

#: ../../tutorial/errors.rst:80
msgid ""
":ref:`bltin-exceptions` lists the built-in exceptions and their meanings."
msgstr ""
":ref:`bltin-exceptions` містить список вбудованих винятків та їх значення."

#: ../../tutorial/errors.rst:86
msgid "Handling Exceptions"
msgstr "Обробка винятків"

#: ../../tutorial/errors.rst:88
msgid ""
"It is possible to write programs that handle selected exceptions. Look at "
"the following example, which asks the user for input until a valid integer "
"has been entered, but allows the user to interrupt the program (using "
":kbd:`Control-C` or whatever the operating system supports); note that a "
"user-generated interruption is signalled by raising the "
":exc:`KeyboardInterrupt` exception. ::"
msgstr ""
"Можна писати програми, які оброблятимуть вибрані винятки. Подивіться на "
"наступний приклад, який запитує у користувача введення, доки не буде введено"
" дійсне ціле число, але дозволяє користувачеві перервати програму (за "
"допомогою :kbd:`Control-C` або іншого, що підтримується операційною "
"системою); зауважте, що створене користувачем переривання сигналізується за "
"допомогою виклику винятку :exc:`KeyboardInterrupt`. ::"

#: ../../tutorial/errors.rst:94
msgid ""
">>> while True:\n"
"...     try:\n"
"...         x = int(input(\"Please enter a number: \"))\n"
"...         break\n"
"...     except ValueError:\n"
"...         print(\"Oops!  That was no valid number.  Try again...\")\n"
"..."
msgstr ""

#: ../../tutorial/errors.rst:102
msgid "The :keyword:`try` statement works as follows."
msgstr "Оператор :keyword:`try` працює наступним чином."

#: ../../tutorial/errors.rst:104
msgid ""
"First, the *try clause* (the statement(s) between the :keyword:`try` and "
":keyword:`except` keywords) is executed."
msgstr ""
"Спочатку виконується пропозиція *try* (вираз(и) між ключовими словами "
":keyword:`try` і :keyword:`except`)."

#: ../../tutorial/errors.rst:107
msgid ""
"If no exception occurs, the *except clause* is skipped and execution of the "
":keyword:`try` statement is finished."
msgstr ""
"Якщо винятків не відбувається, пункт *except* пропускається, і виконання "
"оператора :keyword:`try` завершується."

#: ../../tutorial/errors.rst:110
msgid ""
"If an exception occurs during execution of the :keyword:`try` clause, the "
"rest of the clause is skipped.  Then, if its type matches the exception "
"named after the :keyword:`except` keyword, the *except clause* is executed, "
"and then execution continues after the try/except block."
msgstr ""
"Якщо під час виконання пропозиції :keyword:`try` виникає виняток, решта "
"пропозиції пропускається. Тоді, якщо його тип відповідає винятку, названому "
"за ключовим словом :keyword:`except`, виконується *except*, а потім "
"виконання продовжується після блоку try/except."

#: ../../tutorial/errors.rst:115
msgid ""
"If an exception occurs which does not match the exception named in the "
"*except clause*, it is passed on to outer :keyword:`try` statements; if no "
"handler is found, it is an *unhandled exception* and execution stops with an"
" error message."
msgstr ""

#: ../../tutorial/errors.rst:119
msgid ""
"A :keyword:`try` statement may have more than one *except clause*, to "
"specify handlers for different exceptions.  At most one handler will be "
"executed. Handlers only handle exceptions that occur in the corresponding "
"*try clause*, not in other handlers of the same :keyword:`!try` statement.  "
"An *except clause* may name multiple exceptions as a parenthesized tuple, "
"for example::"
msgstr ""
"Оператор :keyword:`try` може мати більше ніж одне *виключення*, щоб вказати "
"обробники для різних винятків. Буде виконано щонайбільше один обробник. "
"Обробники обробляють лише винятки, які виникають у відповідному *реченні "
"try*, а не в інших обробниках того самого оператора :keyword:`!try`. Речення"
" *except* може називати кілька винятків у вигляді кортежу в дужках, "
"наприклад::"

#: ../../tutorial/errors.rst:125
msgid ""
"... except (RuntimeError, TypeError, NameError):\n"
"...     pass"
msgstr ""

#: ../../tutorial/errors.rst:128
msgid ""
"A class in an :keyword:`except` clause matches exceptions which are "
"instances of the class itself or one of its derived classes (but not the "
"other way around --- an *except clause* listing a derived class does not "
"match instances of its base classes). For example, the following code will "
"print B, C, D in that order::"
msgstr ""

#: ../../tutorial/errors.rst:133
msgid ""
"class B(Exception):\n"
"    pass\n"
"\n"
"class C(B):\n"
"    pass\n"
"\n"
"class D(C):\n"
"    pass\n"
"\n"
"for cls in [B, C, D]:\n"
"    try:\n"
"        raise cls()\n"
"    except D:\n"
"        print(\"D\")\n"
"    except C:\n"
"        print(\"C\")\n"
"    except B:\n"
"        print(\"B\")"
msgstr ""

#: ../../tutorial/errors.rst:152
msgid ""
"Note that if the *except clauses* were reversed (with ``except B`` first), "
"it would have printed B, B, B --- the first matching *except clause* is "
"triggered."
msgstr ""
"Зауважте, що якби *except пункти* були перевернуті (з ``except B`` "
"спочатку), було б надруковано B, B, B --- спрацьовує перше відповідне "
"*except пункт*."

#: ../../tutorial/errors.rst:155
msgid ""
"When an exception occurs, it may have associated values, also known as the "
"exception's *arguments*. The presence and types of the arguments depend on "
"the exception type."
msgstr ""

#: ../../tutorial/errors.rst:159
msgid ""
"The *except clause* may specify a variable after the exception name.  The "
"variable is bound to the exception instance which typically has an ``args`` "
"attribute that stores the arguments. For convenience, builtin exception "
"types define :meth:`~object.__str__` to print all the arguments without "
"explicitly accessing ``.args``.  ::"
msgstr ""

#: ../../tutorial/errors.rst:165
msgid ""
">>> try:\n"
"...     raise Exception('spam', 'eggs')\n"
"... except Exception as inst:\n"
"...     print(type(inst))    # the exception type\n"
"...     print(inst.args)     # arguments stored in .args\n"
"...     print(inst)          # __str__ allows args to be printed directly,\n"
"...                          # but may be overridden in exception subclasses\n"
"...     x, y = inst.args     # unpack args\n"
"...     print('x =', x)\n"
"...     print('y =', y)\n"
"...\n"
"<class 'Exception'>\n"
"('spam', 'eggs')\n"
"('spam', 'eggs')\n"
"x = spam\n"
"y = eggs"
msgstr ""

#: ../../tutorial/errors.rst:182
msgid ""
"The exception's :meth:`~object.__str__` output is printed as the last part "
"('detail') of the message for unhandled exceptions."
msgstr ""

#: ../../tutorial/errors.rst:185
msgid ""
":exc:`BaseException` is the common base class of all exceptions. One of its "
"subclasses, :exc:`Exception`, is the base class of all the non-fatal "
"exceptions. Exceptions which are not subclasses of :exc:`Exception` are not "
"typically handled, because they are used to indicate that the program should"
" terminate. They include :exc:`SystemExit` which is raised by "
":meth:`sys.exit` and :exc:`KeyboardInterrupt` which is raised when a user "
"wishes to interrupt the program."
msgstr ""

#: ../../tutorial/errors.rst:193
msgid ""
":exc:`Exception` can be used as a wildcard that catches (almost) everything."
" However, it is good practice to be as specific as possible with the types "
"of exceptions that we intend to handle, and to allow any unexpected "
"exceptions to propagate on."
msgstr ""

#: ../../tutorial/errors.rst:198
msgid ""
"The most common pattern for handling :exc:`Exception` is to print or log the"
" exception and then re-raise it (allowing a caller to handle the exception "
"as well)::"
msgstr ""

#: ../../tutorial/errors.rst:202
msgid ""
"import sys\n"
"\n"
"try:\n"
"    f = open('myfile.txt')\n"
"    s = f.readline()\n"
"    i = int(s.strip())\n"
"except OSError as err:\n"
"    print(\"OS error:\", err)\n"
"except ValueError:\n"
"    print(\"Could not convert data to an integer.\")\n"
"except Exception as err:\n"
"    print(f\"Unexpected {err=}, {type(err)=}\")\n"
"    raise"
msgstr ""

#: ../../tutorial/errors.rst:216
msgid ""
"The :keyword:`try` ... :keyword:`except` statement has an optional *else "
"clause*, which, when present, must follow all *except clauses*.  It is "
"useful for code that must be executed if the *try clause* does not raise an "
"exception. For example::"
msgstr ""
"Оператор :keyword:`try` ... :keyword:`except` має необов’язкову пропозицію "
"*else*, яка, якщо є, має слідувати за всіма пропозиціями *except*. Це "
"корисно для коду, який потрібно виконати, якщо *речення* try не викликає "
"винятку. Наприклад::"

#: ../../tutorial/errors.rst:221
msgid ""
"for arg in sys.argv[1:]:\n"
"    try:\n"
"        f = open(arg, 'r')\n"
"    except OSError:\n"
"        print('cannot open', arg)\n"
"    else:\n"
"        print(arg, 'has', len(f.readlines()), 'lines')\n"
"        f.close()"
msgstr ""

#: ../../tutorial/errors.rst:230
msgid ""
"The use of the :keyword:`!else` clause is better than adding additional code"
" to the :keyword:`try` clause because it avoids accidentally catching an "
"exception that wasn't raised by the code being protected by the "
":keyword:`!try` ... :keyword:`!except` statement."
msgstr ""
"Використання пропозиції :keyword:`!else` краще, ніж додавання додаткового "
"коду до пропозиції :keyword:`try`, оскільки це дозволяє уникнути випадкового"
" перехоплення виняткової ситуації, яка не була викликана кодом, захищеним "
":keyword:`!try` ... :keyword:`!except` оператор."

#: ../../tutorial/errors.rst:235
msgid ""
"Exception handlers do not handle only exceptions that occur immediately in "
"the *try clause*, but also those that occur inside functions that are called"
" (even indirectly) in the *try clause*. For example::"
msgstr ""

#: ../../tutorial/errors.rst:239
msgid ""
">>> def this_fails():\n"
"...     x = 1/0\n"
"...\n"
">>> try:\n"
"...     this_fails()\n"
"... except ZeroDivisionError as err:\n"
"...     print('Handling run-time error:', err)\n"
"...\n"
"Handling run-time error: division by zero"
msgstr ""

#: ../../tutorial/errors.rst:253
msgid "Raising Exceptions"
msgstr "Створення винятків"

#: ../../tutorial/errors.rst:255
msgid ""
"The :keyword:`raise` statement allows the programmer to force a specified "
"exception to occur. For example::"
msgstr ""
"Оператор :keyword:`raise` дозволяє програмісту примусово викликати певний "
"виняток. Наприклад::"

#: ../../tutorial/errors.rst:258
msgid ""
">>> raise NameError('HiThere')\n"
"Traceback (most recent call last):\n"
"  File \"<stdin>\", line 1, in <module>\n"
"    raise NameError('HiThere')\n"
"NameError: HiThere"
msgstr ""

#: ../../tutorial/errors.rst:264
msgid ""
"The sole argument to :keyword:`raise` indicates the exception to be raised. "
"This must be either an exception instance or an exception class (a class "
"that derives from :class:`BaseException`, such as :exc:`Exception` or one of"
" its subclasses).  If an exception class is passed, it will be implicitly "
"instantiated by calling its constructor with no arguments::"
msgstr ""

#: ../../tutorial/errors.rst:270
msgid "raise ValueError  # shorthand for 'raise ValueError()'"
msgstr ""

#: ../../tutorial/errors.rst:272
msgid ""
"If you need to determine whether an exception was raised but don't intend to"
" handle it, a simpler form of the :keyword:`raise` statement allows you to "
"re-raise the exception::"
msgstr ""
"Якщо вам потрібно визначити, чи був викликаний виняток, але ви не маєте "
"наміру його обробляти, простіша форма оператора :keyword:`raise` дозволяє "
"повторно викликати виняток::"

#: ../../tutorial/errors.rst:276
msgid ""
">>> try:\n"
"...     raise NameError('HiThere')\n"
"... except NameError:\n"
"...     print('An exception flew by!')\n"
"...     raise\n"
"...\n"
"An exception flew by!\n"
"Traceback (most recent call last):\n"
"  File \"<stdin>\", line 2, in <module>\n"
"    raise NameError('HiThere')\n"
"NameError: HiThere"
msgstr ""

#: ../../tutorial/errors.rst:292
msgid "Exception Chaining"
msgstr "З’єднання винятків"

#: ../../tutorial/errors.rst:294
msgid ""
"If an unhandled exception occurs inside an :keyword:`except` section, it "
"will have the exception being handled attached to it and included in the "
"error message::"
msgstr ""

#: ../../tutorial/errors.rst:298
msgid ""
">>> try:\n"
"...     open(\"database.sqlite\")\n"
"... except OSError:\n"
"...     raise RuntimeError(\"unable to handle error\")\n"
"...\n"
"Traceback (most recent call last):\n"
"  File \"<stdin>\", line 2, in <module>\n"
"    open(\"database.sqlite\")\n"
"    ~~~~^^^^^^^^^^^^^^^^^^^\n"
"FileNotFoundError: [Errno 2] No such file or directory: 'database.sqlite'\n"
"\n"
"During handling of the above exception, another exception occurred:\n"
"\n"
"Traceback (most recent call last):\n"
"  File \"<stdin>\", line 4, in <module>\n"
"    raise RuntimeError(\"unable to handle error\")\n"
"RuntimeError: unable to handle error"
msgstr ""

#: ../../tutorial/errors.rst:316
msgid ""
"To indicate that an exception is a direct consequence of another, the "
":keyword:`raise` statement allows an optional :keyword:`from<raise>` "
"clause::"
msgstr ""

#: ../../tutorial/errors.rst:319
msgid ""
"# exc must be exception instance or None.\n"
"raise RuntimeError from exc"
msgstr ""

#: ../../tutorial/errors.rst:322
msgid "This can be useful when you are transforming exceptions. For example::"
msgstr "Це може бути корисним, коли ви перетворюєте винятки. Наприклад::"

#: ../../tutorial/errors.rst:324
msgid ""
">>> def func():\n"
"...     raise ConnectionError\n"
"...\n"
">>> try:\n"
"...     func()\n"
"... except ConnectionError as exc:\n"
"...     raise RuntimeError('Failed to open database') from exc\n"
"...\n"
"Traceback (most recent call last):\n"
"  File \"<stdin>\", line 2, in <module>\n"
"    func()\n"
"    ~~~~^^\n"
"  File \"<stdin>\", line 2, in func\n"
"ConnectionError\n"
"\n"
"The above exception was the direct cause of the following exception:\n"
"\n"
"Traceback (most recent call last):\n"
"  File \"<stdin>\", line 4, in <module>\n"
"    raise RuntimeError('Failed to open database') from exc\n"
"RuntimeError: Failed to open database"
msgstr ""

#: ../../tutorial/errors.rst:346
msgid ""
"It also allows disabling automatic exception chaining using the ``from "
"None`` idiom::"
msgstr ""

#: ../../tutorial/errors.rst:349
msgid ""
">>> try:\n"
"...     open('database.sqlite')\n"
"... except OSError:\n"
"...     raise RuntimeError from None\n"
"...\n"
"Traceback (most recent call last):\n"
"  File \"<stdin>\", line 4, in <module>\n"
"    raise RuntimeError from None\n"
"RuntimeError"
msgstr ""

#: ../../tutorial/errors.rst:359
msgid ""
"For more information about chaining mechanics, see :ref:`bltin-exceptions`."
msgstr ""
"Для отримання додаткової інформації про механіку ланцюжка див. :ref:`bltin-"
"exceptions`."

#: ../../tutorial/errors.rst:365
msgid "User-defined Exceptions"
msgstr "Винятки, визначені користувачем"

#: ../../tutorial/errors.rst:367
msgid ""
"Programs may name their own exceptions by creating a new exception class "
"(see :ref:`tut-classes` for more about Python classes).  Exceptions should "
"typically be derived from the :exc:`Exception` class, either directly or "
"indirectly."
msgstr ""
"Програми можуть називати свої власні винятки, створюючи новий клас винятків "
"(перегляньте :ref:`tut-classes`, щоб дізнатися більше про класи Python). "
"Винятки зазвичай мають бути похідними від класу :exc:`Exception`, прямо чи "
"опосередковано."

#: ../../tutorial/errors.rst:371
msgid ""
"Exception classes can be defined which do anything any other class can do, "
"but are usually kept simple, often only offering a number of attributes that"
" allow information about the error to be extracted by handlers for the "
"exception."
msgstr ""
"Можна визначити класи винятків, які роблять усе, що може зробити будь-який "
"інший клас, але зазвичай вони прості, часто пропонують лише ряд атрибутів, "
"які дозволяють обробникам витягувати інформацію про помилку для винятку."

#: ../../tutorial/errors.rst:375
msgid ""
"Most exceptions are defined with names that end in \"Error\", similar to the"
" naming of the standard exceptions."
msgstr ""
"Більшість винятків визначаються іменами, які закінчуються на \"Помилка\", "
"подібно до назв стандартних винятків."

#: ../../tutorial/errors.rst:378
msgid ""
"Many standard modules define their own exceptions to report errors that may "
"occur in functions they define."
msgstr ""

#: ../../tutorial/errors.rst:385
msgid "Defining Clean-up Actions"
msgstr "Визначення дій з очищення"

#: ../../tutorial/errors.rst:387
msgid ""
"The :keyword:`try` statement has another optional clause which is intended "
"to define clean-up actions that must be executed under all circumstances.  "
"For example::"
msgstr ""
"Інструкція :keyword:`try` має інше необов’язкове положення, призначене для "
"визначення дій очищення, які необхідно виконувати за будь-яких обставин. "
"Наприклад::"

#: ../../tutorial/errors.rst:391
msgid ""
">>> try:\n"
"...     raise KeyboardInterrupt\n"
"... finally:\n"
"...     print('Goodbye, world!')\n"
"...\n"
"Goodbye, world!\n"
"Traceback (most recent call last):\n"
"  File \"<stdin>\", line 2, in <module>\n"
"    raise KeyboardInterrupt\n"
"KeyboardInterrupt"
msgstr ""

#: ../../tutorial/errors.rst:402
msgid ""
"If a :keyword:`finally` clause is present, the :keyword:`!finally` clause "
"will execute as the last task before the :keyword:`try` statement completes."
" The :keyword:`!finally` clause runs whether or not the :keyword:`!try` "
"statement produces an exception. The following points discuss more complex "
"cases when an exception occurs:"
msgstr ""
"Якщо присутня пропозиція :keyword:`finally`, пропозиція :keyword:`!finally` "
"виконуватиметься як останнє завдання перед завершенням інструкції "
":keyword:`try`. Речення :keyword:`!finally` виконується незалежно від того, "
"створює виняток оператор :keyword:`!try` чи ні. У наступних пунктах "
"розглядаються більш складні випадки, коли виникає виняток:"

#: ../../tutorial/errors.rst:408
msgid ""
"If an exception occurs during execution of the :keyword:`!try` clause, the "
"exception may be handled by an :keyword:`except` clause. If the exception is"
" not handled by an :keyword:`!except` clause, the exception is re-raised "
"after the :keyword:`!finally` clause has been executed."
msgstr ""
"Якщо виняток виникає під час виконання пропозиції :keyword:`!try`, виняток "
"може бути оброблено за допомогою пропозиції :keyword:`except`. Якщо виняток "
"не обробляється пропозицією :keyword:`!except`, виняток виникає повторно "
"після того, як пропозиція :keyword:`!finally` буде виконана."

#: ../../tutorial/errors.rst:414
msgid ""
"An exception could occur during execution of an :keyword:`!except` or "
":keyword:`!else` clause. Again, the exception is re-raised after the "
":keyword:`!finally` clause has been executed."
msgstr ""
"Виняток може статися під час виконання пропозиції :keyword:`!except` або "
":keyword:`!else`. Знову ж таки, виняток повторно викликається після "
"виконання пункту :keyword:`!finally`."

#: ../../tutorial/errors.rst:418
msgid ""
"If the :keyword:`!finally` clause executes a :keyword:`break`, "
":keyword:`continue` or :keyword:`return` statement, exceptions are not re-"
"raised."
msgstr ""
"Якщо пропозиція :keyword:`!finally` виконує оператор :keyword:`break`, "
":keyword:`continue` або :keyword:`return`, винятки не виникають повторно."

#: ../../tutorial/errors.rst:422
msgid ""
"If the :keyword:`!try` statement reaches a :keyword:`break`, "
":keyword:`continue` or :keyword:`return` statement, the :keyword:`!finally` "
"clause will execute just prior to the :keyword:`!break`, "
":keyword:`!continue` or :keyword:`!return` statement's execution."
msgstr ""
"Якщо оператор :keyword:`!try` досягає оператора :keyword:`break`, "
":keyword:`continue` або :keyword:`return`, пункт :keyword:`!finally` буде "
"виконано безпосередньо перед :keyword:`!break`, :keyword:`!continue` або "
":keyword:`!return` виконання оператора."

#: ../../tutorial/errors.rst:428
msgid ""
"If a :keyword:`!finally` clause includes a :keyword:`!return` statement, the"
" returned value will be the one from the :keyword:`!finally` clause's "
":keyword:`!return` statement, not the value from the :keyword:`!try` "
"clause's :keyword:`!return` statement."
msgstr ""
"Якщо пропозиція :keyword:`!finally` містить інструкцію :keyword:`!return`, "
"поверненим значенням буде значення з інструкції :keyword:`!return` "
"пропозиції :keyword:`!finally`, а не значення з оператора :keyword:`!return`"
" пункту :keyword:`!try`."

#: ../../tutorial/errors.rst:434
msgid "For example::"
msgstr "Наприклад::"

#: ../../tutorial/errors.rst:436
msgid ""
">>> def bool_return():\n"
"...     try:\n"
"...         return True\n"
"...     finally:\n"
"...         return False\n"
"...\n"
">>> bool_return()\n"
"False"
msgstr ""

#: ../../tutorial/errors.rst:445
msgid "A more complicated example::"
msgstr "Більш складний приклад::"

#: ../../tutorial/errors.rst:447
msgid ""
">>> def divide(x, y):\n"
"...     try:\n"
"...         result = x / y\n"
"...     except ZeroDivisionError:\n"
"...         print(\"division by zero!\")\n"
"...     else:\n"
"...         print(\"result is\", result)\n"
"...     finally:\n"
"...         print(\"executing finally clause\")\n"
"...\n"
">>> divide(2, 1)\n"
"result is 2.0\n"
"executing finally clause\n"
">>> divide(2, 0)\n"
"division by zero!\n"
"executing finally clause\n"
">>> divide(\"2\", \"1\")\n"
"executing finally clause\n"
"Traceback (most recent call last):\n"
"  File \"<stdin>\", line 1, in <module>\n"
"    divide(\"2\", \"1\")\n"
"    ~~~~~~^^^^^^^^^^\n"
"  File \"<stdin>\", line 3, in divide\n"
"    result = x / y\n"
"             ~~^~~\n"
"TypeError: unsupported operand type(s) for /: 'str' and 'str'"
msgstr ""

#: ../../tutorial/errors.rst:474
msgid ""
"As you can see, the :keyword:`finally` clause is executed in any event.  The"
" :exc:`TypeError` raised by dividing two strings is not handled by the "
":keyword:`except` clause and therefore re-raised after the "
":keyword:`!finally` clause has been executed."
msgstr ""
"Як бачите, пункт :keyword:`finally` виконується в будь-якій події. Помилка "
":exc:`TypeError`, викликана розділенням двох рядків, не обробляється "
"пропозицією :keyword:`except` і тому повторно виникає після виконання "
"пропозиції :keyword:`!finally`."

#: ../../tutorial/errors.rst:479
msgid ""
"In real world applications, the :keyword:`finally` clause is useful for "
"releasing external resources (such as files or network connections), "
"regardless of whether the use of the resource was successful."
msgstr ""
"У додатках реального світу пункт :keyword:`finally` корисний для звільнення "
"зовнішніх ресурсів (таких як файли або мережеві підключення), незалежно від "
"того, чи було використання ресурсу успішним."

#: ../../tutorial/errors.rst:487
msgid "Predefined Clean-up Actions"
msgstr "Попередньо визначені дії з очищення"

#: ../../tutorial/errors.rst:489
msgid ""
"Some objects define standard clean-up actions to be undertaken when the "
"object is no longer needed, regardless of whether or not the operation using"
" the object succeeded or failed. Look at the following example, which tries "
"to open a file and print its contents to the screen. ::"
msgstr ""
"Деякі об’єкти визначають стандартні дії з очищення, які необхідно виконати, "
"коли об’єкт більше не потрібний, незалежно від того, чи була операція з "
"використанням об’єкта успішною чи невдалою. Подивіться на наступний приклад,"
" який намагається відкрити файл і вивести його вміст на екран. ::"

#: ../../tutorial/errors.rst:494
msgid ""
"for line in open(\"myfile.txt\"):\n"
"    print(line, end=\"\")"
msgstr ""

#: ../../tutorial/errors.rst:497
msgid ""
"The problem with this code is that it leaves the file open for an "
"indeterminate amount of time after this part of the code has finished "
"executing. This is not an issue in simple scripts, but can be a problem for "
"larger applications. The :keyword:`with` statement allows objects like files"
" to be used in a way that ensures they are always cleaned up promptly and "
"correctly. ::"
msgstr ""
"Проблема з цим кодом полягає в тому, що він залишає файл відкритим протягом "
"невизначеного періоду часу після завершення виконання цієї частини коду. Це "
"не проблема для простих сценаріїв, але може бути проблемою для великих "
"програм. Оператор :keyword:`with` дозволяє використовувати такі об’єкти, як "
"файли, таким чином, щоб вони завжди були своєчасно та правильно очищені. ::"

#: ../../tutorial/errors.rst:503
msgid ""
"with open(\"myfile.txt\") as f:\n"
"    for line in f:\n"
"        print(line, end=\"\")"
msgstr ""

#: ../../tutorial/errors.rst:507
msgid ""
"After the statement is executed, the file *f* is always closed, even if a "
"problem was encountered while processing the lines. Objects which, like "
"files, provide predefined clean-up actions will indicate this in their "
"documentation."
msgstr ""
"Після виконання виразу файл *f* завжди закривається, навіть якщо під час "
"обробки рядків виникла проблема. Об’єкти, які, як і файли, забезпечують "
"попередньо визначені дії очищення, вкажуть це у своїй документації."

#: ../../tutorial/errors.rst:515
msgid "Raising and Handling Multiple Unrelated Exceptions"
msgstr ""

#: ../../tutorial/errors.rst:517
msgid ""
"There are situations where it is necessary to report several exceptions that"
" have occurred. This is often the case in concurrency frameworks, when "
"several tasks may have failed in parallel, but there are also other use "
"cases where it is desirable to continue execution and collect multiple "
"errors rather than raise the first exception."
msgstr ""

#: ../../tutorial/errors.rst:523
msgid ""
"The builtin :exc:`ExceptionGroup` wraps a list of exception instances so "
"that they can be raised together. It is an exception itself, so it can be "
"caught like any other exception. ::"
msgstr ""

#: ../../tutorial/errors.rst:527
msgid ""
">>> def f():\n"
"...     excs = [OSError('error 1'), SystemError('error 2')]\n"
"...     raise ExceptionGroup('there were problems', excs)\n"
"...\n"
">>> f()\n"
"  + Exception Group Traceback (most recent call last):\n"
"  |   File \"<stdin>\", line 1, in <module>\n"
"  |     f()\n"
"  |     ~^^\n"
"  |   File \"<stdin>\", line 3, in f\n"
"  |     raise ExceptionGroup('there were problems', excs)\n"
"  | ExceptionGroup: there were problems (2 sub-exceptions)\n"
"  +-+---------------- 1 ----------------\n"
"    | OSError: error 1\n"
"    +---------------- 2 ----------------\n"
"    | SystemError: error 2\n"
"    +------------------------------------\n"
">>> try:\n"
"...     f()\n"
"... except Exception as e:\n"
"...     print(f'caught {type(e)}: e')\n"
"...\n"
"caught <class 'ExceptionGroup'>: e\n"
">>>"
msgstr ""

#: ../../tutorial/errors.rst:552
msgid ""
"By using ``except*`` instead of ``except``, we can selectively handle only "
"the exceptions in the group that match a certain type. In the following "
"example, which shows a nested exception group, each ``except*`` clause "
"extracts from the group exceptions of a certain type while letting all other"
" exceptions propagate to other clauses and eventually to be reraised. ::"
msgstr ""

#: ../../tutorial/errors.rst:559
msgid ""
">>> def f():\n"
"...     raise ExceptionGroup(\n"
"...         \"group1\",\n"
"...         [\n"
"...             OSError(1),\n"
"...             SystemError(2),\n"
"...             ExceptionGroup(\n"
"...                 \"group2\",\n"
"...                 [\n"
"...                     OSError(3),\n"
"...                     RecursionError(4)\n"
"...                 ]\n"
"...             )\n"
"...         ]\n"
"...     )\n"
"...\n"
">>> try:\n"
"...     f()\n"
"... except* OSError as e:\n"
"...     print(\"There were OSErrors\")\n"
"... except* SystemError as e:\n"
"...     print(\"There were SystemErrors\")\n"
"...\n"
"There were OSErrors\n"
"There were SystemErrors\n"
"  + Exception Group Traceback (most recent call last):\n"
"  |   File \"<stdin>\", line 2, in <module>\n"
"  |     f()\n"
"  |     ~^^\n"
"  |   File \"<stdin>\", line 2, in f\n"
"  |     raise ExceptionGroup(\n"
"  |     ...<12 lines>...\n"
"  |     )\n"
"  | ExceptionGroup: group1 (1 sub-exception)\n"
"  +-+---------------- 1 ----------------\n"
"    | ExceptionGroup: group2 (1 sub-exception)\n"
"    +-+---------------- 1 ----------------\n"
"      | RecursionError: 4\n"
"      +------------------------------------\n"
">>>"
msgstr ""

#: ../../tutorial/errors.rst:600
msgid ""
"Note that the exceptions nested in an exception group must be instances, not"
" types. This is because in practice the exceptions would typically be ones "
"that have already been raised and caught by the program, along the following"
" pattern::"
msgstr ""

#: ../../tutorial/errors.rst:605
msgid ""
">>> excs = []\n"
"... for test in tests:\n"
"...     try:\n"
"...         test.run()\n"
"...     except Exception as e:\n"
"...         excs.append(e)\n"
"...\n"
">>> if excs:\n"
"...    raise ExceptionGroup(\"Test Failures\", excs)\n"
"..."
msgstr ""

#: ../../tutorial/errors.rst:620
msgid "Enriching Exceptions with Notes"
msgstr ""

#: ../../tutorial/errors.rst:622
msgid ""
"When an exception is created in order to be raised, it is usually "
"initialized with information that describes the error that has occurred. "
"There are cases where it is useful to add information after the exception "
"was caught. For this purpose, exceptions have a method ``add_note(note)`` "
"that accepts a string and adds it to the exception's notes list. The "
"standard traceback rendering includes all notes, in the order they were "
"added, after the exception. ::"
msgstr ""

#: ../../tutorial/errors.rst:629
msgid ""
">>> try:\n"
"...     raise TypeError('bad type')\n"
"... except Exception as e:\n"
"...     e.add_note('Add some information')\n"
"...     e.add_note('Add some more information')\n"
"...     raise\n"
"...\n"
"Traceback (most recent call last):\n"
"  File \"<stdin>\", line 2, in <module>\n"
"    raise TypeError('bad type')\n"
"TypeError: bad type\n"
"Add some information\n"
"Add some more information\n"
">>>"
msgstr ""

#: ../../tutorial/errors.rst:644
msgid ""
"For example, when collecting exceptions into an exception group, we may want"
" to add context information for the individual errors. In the following each"
" exception in the group has a note indicating when this error has occurred. "
"::"
msgstr ""

#: ../../tutorial/errors.rst:648
msgid ""
">>> def f():\n"
"...     raise OSError('operation failed')\n"
"...\n"
">>> excs = []\n"
">>> for i in range(3):\n"
"...     try:\n"
"...         f()\n"
"...     except Exception as e:\n"
"...         e.add_note(f'Happened in Iteration {i+1}')\n"
"...         excs.append(e)\n"
"...\n"
">>> raise ExceptionGroup('We have some problems', excs)\n"
"  + Exception Group Traceback (most recent call last):\n"
"  |   File \"<stdin>\", line 1, in <module>\n"
"  |     raise ExceptionGroup('We have some problems', excs)\n"
"  | ExceptionGroup: We have some problems (3 sub-exceptions)\n"
"  +-+---------------- 1 ----------------\n"
"    | Traceback (most recent call last):\n"
"    |   File \"<stdin>\", line 3, in <module>\n"
"    |     f()\n"
"    |     ~^^\n"
"    |   File \"<stdin>\", line 2, in f\n"
"    |     raise OSError('operation failed')\n"
"    | OSError: operation failed\n"
"    | Happened in Iteration 1\n"
"    +---------------- 2 ----------------\n"
"    | Traceback (most recent call last):\n"
"    |   File \"<stdin>\", line 3, in <module>\n"
"    |     f()\n"
"    |     ~^^\n"
"    |   File \"<stdin>\", line 2, in f\n"
"    |     raise OSError('operation failed')\n"
"    | OSError: operation failed\n"
"    | Happened in Iteration 2\n"
"    +---------------- 3 ----------------\n"
"    | Traceback (most recent call last):\n"
"    |   File \"<stdin>\", line 3, in <module>\n"
"    |     f()\n"
"    |     ~^^\n"
"    |   File \"<stdin>\", line 2, in f\n"
"    |     raise OSError('operation failed')\n"
"    | OSError: operation failed\n"
"    | Happened in Iteration 3\n"
"    +------------------------------------\n"
">>>"
msgstr ""
